<?xml version="1.0" encoding="utf-8"?>
<!-- This URDF was automatically created by SolidWorks to URDF Exporter! Originally created by Stephen Brawner (brawner@gmail.com) 
     Commit Version: 1.6.0-1-g15f4949  Build Version: 1.6.7594.29634
     For more information, please see http://wiki.ros.org/sw_urdf_exporter -->
<robot
  name="rm_75_6f_description">
  <link
    name="base_link">
    <inertial>
      <origin
        xyz="0.00043296 3.5291E-05 0.059942"
        rpy="0 0 0" />
      <mass
        value="0.84105" />
      <inertia
        ixx="0.0017261"
        ixy="2.5275E-06"
        ixz="3.6769E-05"
        iyy="0.0017099"
        iyz="-1.68E-06"
        izz="0.00090402" />
    </inertial>
    <visual>
      <origin
        xyz="0 0 0"
        rpy="0 0 0" />
      <geometry>
        <mesh
          filename="file://$(find rm_description)/meshes/rm_75_6f_arm/base_link.STL" />
      </geometry>
      <material
        name="">
        <color
          rgba="1 1 1 1" />
      </material>
    </visual>
    <collision>
      <origin
        xyz="0 0 0"
        rpy="0 0 0" />
      <geometry>
        <mesh
          filename="file://$(find rm_description)/meshes/rm_75_6f_arm/base_link.STL" />
      </geometry>
    </collision>
  </link>
  <link
    name="Link1">
    <inertial>
      <origin
        xyz="-2.1376E-07 0.025186 -0.021108"
        rpy="0 0 0" />
      <mass
        value="0.59356" />
      <inertia
        ixx="0.0012661"
        ixy="-9.8019E-09"
        ixz="-1.2951E-08"
        iyy="0.00056135"
        iyz="-0.00021122"
        izz="0.0011817" />
    </inertial>
    <visual>
      <origin
        xyz="0 0 0"
        rpy="0 0 0" />
      <geometry>
        <mesh
          filename="file://$(find rm_description)/meshes/rm_75_6f_arm/Link1.STL" />
      </geometry>
      <material
        name="">
        <color
          rgba="1 1 1 1" />
      </material>
    </visual>
    <collision>
      <origin
        xyz="0 0 0"
        rpy="0 0 0" />
      <geometry>
        <mesh
          filename="file://$(find rm_description)/meshes/rm_75_6f_arm/Link1.STL" />
      </geometry>
    </collision>
  </link>
  <joint
    name="joint1"
    type="revolute">
    <origin
      xyz="0 0 0.2405"
      rpy="-1.5708 0 0" />
    <parent
      link="base_link" />
    <child
      link="Link1" />
    <axis
      xyz="0 -1 0" />
    <limit
      lower="-3.107"
      upper="3.107"
      effort="100"
      velocity="1" />
  </joint>
  <link
    name="Link2">
    <inertial>
      <origin
        xyz="4.1111E-07 0.011078 0.076129"
        rpy="0 0 0" />
      <mass
        value="0.43285" />
      <inertia
        ixx="0.0012584"
        ixy="5.6315E-09"
        ixz="1.3348E-09"
        iyy="0.0012225"
        iyz="0.000279"
        izz="0.00031747" />
    </inertial>
    <visual>
      <origin
        xyz="0 0 0"
        rpy="0 0 0" />
      <geometry>
        <mesh
          filename="file://$(find rm_description)/meshes/rm_75_6f_arm/Link2.STL" />
      </geometry>
      <material
        name="">
        <color
          rgba="1 1 1 1" />
      </material>
    </visual>
    <collision>
      <origin
        xyz="0 0 0"
        rpy="0 0 0" />
      <geometry>
        <mesh
          filename="file://$(find rm_description)/meshes/rm_75_6f_arm/Link2.STL" />
      </geometry>
    </collision>
  </link>
  <joint
    name="joint2"
    type="revolute">
    <origin
      xyz="0 0 0"
      rpy="1.5708 0 0" />
    <parent
      link="Link1" />
    <child
      link="Link2" />
    <axis
      xyz="0 1 0" />
    <limit
      lower="-2.269"
      upper="2.269"
      effort="100"
      velocity="1" />
  </joint>
  <link
    name="Link3">
    <inertial>
      <origin
        xyz="-4.7932E-07 0.027347 -0.023544"
        rpy="0 0 0" />
      <mass
        value="0.43132" />
      <inertia
        ixx="0.00079433"
        ixy="1.0334E-08"
        ixz="-2.329E-09"
        iyy="0.00031507"
        iyz="-0.00014262"
        izz="0.00073037" />
    </inertial>
    <visual>
      <origin
        xyz="0 0 0"
        rpy="0 0 0" />
      <geometry>
        <mesh
          filename="file://$(find rm_description)/meshes/rm_75_6f_arm/Link3.STL" />
      </geometry>
      <material
        name="">
        <color
          rgba="1 1 1 1" />
      </material>
    </visual>
    <collision>
      <origin
        xyz="0 0 0"
        rpy="0 0 0" />
      <geometry>
        <mesh
          filename="file://$(find rm_description)/meshes/rm_75_6f_arm/Link3.STL" />
      </geometry>
    </collision>
  </link>
  <joint
    name="joint3"
    type="revolute">
    <origin
      xyz="0 0 0.256"
      rpy="-1.5708 0 0" />
    <parent
      link="Link2" />
    <child
      link="Link3" />
    <axis
      xyz="0 -1 0" />
    <limit
      lower="-3.107"
      upper="3.107"
      effort="100"
      velocity="1" />
  </joint>
  <link
    name="Link4">
    <inertial>
      <origin
        xyz="5.0444E-06 0.010569 0.059593"
        rpy="0 0 0" />
      <mass
        value="0.28963" />
      <inertia
        ixx="0.00063737"
        ixy="-3.8666E-08"
        ixz="7.0522E-08"
        iyy="0.00061418"
        iyz="0.00014461"
        izz="0.00015648" />
    </inertial>
    <visual>
      <origin
        xyz="0 0 0"
        rpy="0 0 0" />
      <geometry>
        <mesh
          filename="file://$(find rm_description)/meshes/rm_75_6f_arm/Link4.STL" />
      </geometry>
      <material
        name="">
        <color
          rgba="1 1 1 1" />
      </material>
    </visual>
    <collision>
      <origin
        xyz="0 0 0"
        rpy="0 0 0" />
      <geometry>
        <mesh
          filename="file://$(find rm_description)/meshes/rm_75_6f_arm/Link4.STL" />
      </geometry>
    </collision>
  </link>
  <joint
    name="joint4"
    type="revolute">
    <origin
      xyz="0 0 0"
      rpy="1.5708 0 0" />
    <parent
      link="Link3" />
    <child
      link="Link4" />
    <axis
      xyz="0 1 0" />
    <limit
      lower="-2.356"
      upper="2.356"
      effort="100"
      velocity="1" />
  </joint>
  <link
    name="Link5">
    <inertial>
      <origin
        xyz="1.1466E-06 0.021541 -0.018041"
        rpy="0 0 0" />
      <mass
        value="0.23941" />
      <inertia
        ixx="0.00028594"
        ixy="1.8435E-09"
        ixz="2.6611E-09"
        iyy="0.00011989"
        iyz="-4.4238E-05"
        izz="0.00026273" />
    </inertial>
    <visual>
      <origin
        xyz="0 0 0"
        rpy="0 0 0" />
      <geometry>
        <mesh
          filename="file://$(find rm_description)/meshes/rm_75_6f_arm/Link5.STL" />
      </geometry>
      <material
        name="">
        <color
          rgba="1 1 1 1" />
      </material>
    </visual>
    <collision>
      <origin
        xyz="0 0 0"
        rpy="0 0 0" />
      <geometry>
        <mesh
          filename="file://$(find rm_description)/meshes/rm_75_6f_arm/Link5.STL" />
      </geometry>
    </collision>
  </link>
  <joint
    name="joint5"
    type="revolute">
    <origin
      xyz="0 0 0.21"
      rpy="-1.5708 0 0" />
    <parent
      link="Link4" />
    <child
      link="Link5" />
    <axis
      xyz="0 -1 0" />
    <limit
      lower="-3.107"
      upper="3.107"
      effort="100"
      velocity="1" />
  </joint>
  <link
    name="Link6">
    <inertial>
      <origin
        xyz="4.5754E-06 0.0073681 0.059382"
        rpy="0 0 0" />
      <mass
        value="0.21879" />
      <inertia
        ixx="0.00035053"
        ixy="-1.7437E-08"
        ixz="3.1653E-08"
        iyy="0.00033447"
        iyz="7.824E-05"
        izz="0.00010492" />
    </inertial>
    <visual>
      <origin
        xyz="0 0 0"
        rpy="0 0 0" />
      <geometry>
        <mesh
          filename="file://$(find rm_description)/meshes/rm_75_6f_arm/Link6.STL" />
      </geometry>
      <material
        name="">
        <color
          rgba="1 1 1 1" />
      </material>
    </visual>
    <collision>
      <origin
        xyz="0 0 0"
        rpy="0 0 0" />
      <geometry>
        <mesh
          filename="file://$(find rm_description)/meshes/rm_75_6f_arm/Link6.STL" />
      </geometry>
    </collision>
  </link>
  <joint
    name="joint6"
    type="revolute">
    <origin
      xyz="0 0 0"
      rpy="1.5708 0 0" />
    <parent
      link="Link5" />
    <child
      link="Link6" />
    <axis
      xyz="0 1 0" />
    <limit
      lower="-2.234"
      upper="2.234"
      effort="100"
      velocity="1" />
  </joint>
  <link
    name="Link7">
    <inertial>
      <origin
        xyz="0.00032231 -0.0001782 -0.028676"
        rpy="0 0 0" />
      <mass
        value="0.14433" />
      <inertia
        ixx="3.6119E-05"
        ixy="-1.3242E-06"
        ixz="-3.2733E-08"
        iyy="3.4626E-05"
        iyz="7.6694E-09"
        izz="6.1463E-05" />
    </inertial>
    <visual>
      <origin
        xyz="0 0 0"
        rpy="0 0 0" />
      <geometry>
        <mesh
          filename="file://$(find rm_description)/meshes/rm_75_6f_arm/Link7.STL" />
      </geometry>
      <material
        name="">
        <color
          rgba="1 1 1 1" />
      </material>
    </visual>
    <collision>
      <origin
        xyz="0 0 0"
        rpy="0 0 0" />
      <geometry>
        <mesh
          filename="file://$(find rm_description)/meshes/rm_75_6f_arm/Link7.STL" />
      </geometry>
    </collision>
  </link>
  <joint
    name="joint7"
    type="revolute">
    <origin
      xyz="0 0 0.1725"
      rpy="0 0 0" />
    <parent
      link="Link6" />
    <child
      link="Link7" />
    <axis
      xyz="0 0 1" />
    <limit
      lower="-6.283"
      upper="6.283"
      effort="100"
      velocity="1" />
  </joint>

  <!-- TODO 需要将后续所有部件进行拆解，在导入的时候根据配置对urdf或是xacro进行拼接 -->
  <!-- connect to camera -->
  <link
    name="camera_connect">
    <inertial>
      <origin
        xyz="0.045819 0 0.0039533"
        rpy="0 0 0" />
      <mass
        value="0.051365" />
      <inertia
        ixx="1.5947E-05"
        ixy="2.2017E-20"
        ixz="-1.4477E-07"
        iyy="8.6653E-05"
        iyz="-1.9465E-21"
        izz="0.00010204" />
    </inertial>
    <visual>
      <origin
        xyz="0 0 0"
        rpy="0 0 0" />
      <geometry>
        <mesh
          filename="file://$(find rm_description)/meshes/gripper/camera_connect.STL" />
      </geometry>
      <material
        name="">
        <color
          rgba="0.79216 0.81961 0.93333 1" />
      </material>
    </visual>
    <collision>
      <origin
        xyz="0 0 0"
        rpy="0 0 0" />
      <geometry>
        <mesh
          filename="file://$(find rm_description)/meshes/gripper/camera_connect.STL" />
      </geometry>
    </collision>
  </link>
  <joint
    name="arm_joint_camera"
    type="fixed">
    <origin
      xyz="0 0 0"
      rpy="0 0 0" />
    <parent
      link="Link7" />
    <child
      link="camera_connect" />
    <axis
      xyz="0 0 0" />
  </joint>

  <!--定义一个工具坐标系-->
  <link name="gripper_tip_link"/>
  <joint name="gripper_tip_joint" type="fixed">
    <origin xyz="0 0 0.1522" rpy="0 0 0"/>
    <parent link="Link7"/>
    <child link="gripper_tip_link"/>
  </joint>
  <!--通过相机标定结果发布坐标系-->
  <link name="hand_link"/>
  <joint name="hand_camera_joint" type="fixed">
    <origin xyz="9.118397057093950708e-02 -1.184690085767839060e-02 -1.088632721090737610e-01" rpy="-3.141592653589793 -1.5707963267948966 0.0"/>
    <parent link="gripper_tip_link"/>
    <child link="hand_link"/>
  </joint>

  <!-- gripper -->
  <link
    name="gripper_base_link">
    <inertial>
      <origin
        xyz="-2.6792E-06 1.4343E-05 -0.040955"
        rpy="0 0 0" />
      <mass
        value="0.075349" />
      <inertia
        ixx="6.9695E-05"
        ixy="-2.8955E-12"
        ixz="1.2653E-08"
        iyy="6.0426E-05"
        iyz="2.2585E-08"
        izz="1.9195E-05" />
    </inertial>
    <visual>
      <origin
        xyz="0 0 0"
        rpy="0 0 0" />
      <geometry>
        <mesh
          filename="file://$(find rm_description)/meshes/gripper/gripper_base_link.STL" />
      </geometry>
      <material
        name="">
        <color
          rgba="0.79216 0.81961 0.93333 1" />
      </material>
    </visual>
    <collision>
      <origin
        xyz="0 0 0"
        rpy="0 0 0" />
      <geometry>
        <mesh
          filename="file://$(find rm_description)/meshes/gripper/gripper_base_link.STL" />
      </geometry>
    </collision>
  </link>

  <joint name="arm_joint_gripper" type="fixed">
    <origin xyz="0 0 0.008" rpy="0 0 0" />
    <parent link="camera_connect" />
    <child link="gripper_base_link" />
  </joint>

  <link
    name="gripper_Link1">
    <inertial>
      <origin
        xyz="0.0001 0.0085832 0.013664"
        rpy="0 0 0" />
      <mass
        value="0.0024857" />
      <inertia
        ixx="5.8907E-07"
        ixy="1.3343E-19"
        ixz="4.2984E-19"
        iyy="5.2237E-07"
        iyz="-2.5787E-07"
        izz="2.7386E-07" />
    </inertial>
    <visual>
      <origin
        xyz="0 0 0"
        rpy="0 0 0" />
      <geometry>
        <mesh
          filename="file://$(find rm_description)/meshes/gripper/gripper_Link1.STL" />
      </geometry>
      <material
        name="">
        <color
          rgba="0.79216 0.81961 0.93333 1" />
      </material>
    </visual>
    <collision>
      <origin
        xyz="0 0 0"
        rpy="0 0 0" />
      <geometry>
        <mesh
          filename="file://$(find rm_description)/meshes/gripper/gripper_Link1.STL" />
      </geometry>
    </collision>
  </link>
  <joint
    name="gripper_joint1"
    type="revolute">
    <origin
      xyz="0 -0.04 0.09"
      rpy="0.8663 0 0" />
    <parent
      link="gripper_base_link" />
    <child
      link="gripper_Link1" />
    <axis
      xyz="1 0 0" />
    <limit
      lower="-1.5708"
      upper="1.5708"
      effort="100"
      velocity="1" />

  </joint>
  <link
    name="gripper_Link2">
    <inertial>
      <origin
        xyz="9.9997E-05 0.011846 0.011367"
        rpy="0 0 0" />
      <mass
        value="0.0044927" />
      <inertia
        ixx="4.099E-07"
        ixy="-7.8736E-14"
        ixz="-7.8248E-14"
        iyy="4.2946E-07"
        iyz="-3.8654E-08"
        izz="1.6162E-07" />
    </inertial>
    <visual>
      <origin
        xyz="0 0 0"
        rpy="0 0 0" />
      <geometry>
        <mesh
          filename="file://$(find rm_description)/meshes/gripper/gripper_Link2.STL" />
      </geometry>
      <material
        name="">
        <color
          rgba="0.79216 0.81961 0.93333 1" />
      </material>
    </visual>
    <collision>
      <origin
        xyz="0 0 0"
        rpy="0 0 0" />
      <geometry>
        <mesh
          filename="file://$(find rm_description)/meshes/gripper/gripper_Link2.STL" />
      </geometry>
    </collision>
  </link>
  <joint
    name="gripper_joint2"
    type="revolute">
    <origin
      xyz="0 0.022341 0.035565"
      rpy="-0.8663 0 0" />
    <parent
      link="gripper_Link1" />
    <child
      link="gripper_Link2" />
    <axis
      xyz="-1 0 0" />
    <limit
      lower="-1.5708"
      upper="1.5708"
      effort="100"
      velocity="1" />
    <mimic
      joint="gripper_joint1"
      multiplier="1"
      offset="0" />
  </joint>
  <link
    name="gripper_Link3">
    <inertial>
      <origin
        xyz="0.0001 -0.0085832 0.013664"
        rpy="0 0 0" />
      <mass
        value="0.0024857" />
      <inertia
        ixx="5.8907E-07"
        ixy="-3.3324E-19"
        ixz="3.1193E-19"
        iyy="5.2237E-07"
        iyz="2.5787E-07"
        izz="2.7386E-07" />
    </inertial>
    <visual>
      <origin
        xyz="0 0 0"
        rpy="0 0 0" />
      <geometry>
        <mesh
          filename="file://$(find rm_description)/meshes/gripper/gripper_Link3.STL" />
      </geometry>
      <material
        name="">
        <color
          rgba="0.79216 0.81961 0.93333 1" />
      </material>
    </visual>
    <collision>
      <origin
        xyz="0 0 0"
        rpy="0 0 0" />
      <geometry>
        <mesh
          filename="file://$(find rm_description)/meshes/gripper/gripper_Link3.STL" />
      </geometry>
    </collision>
  </link>
  <joint
    name="gripper_joint3"
    type="revolute">
    <origin
      xyz="0 0.04 0.09"
      rpy="-0.8663 0 0" />
    <parent
      link="gripper_base_link" />
    <child
      link="gripper_Link3" />
    <axis
      xyz="1 0 0" />
    <limit
      lower="-1.5708"
      upper="1.5708"
      effort="100"
      velocity="1" />
    <!-- <mimic
      joint="gripper_joint1"
      multiplier="1"
      offset="0" />  -->
  </joint>
  <link
    name="gripper_Link4">
    <inertial>
      <origin
        xyz="9.9999E-05 -0.011846 0.011367"
        rpy="0 0 0" />
      <mass
        value="0.0044926" />
      <inertia
        ixx="4.099E-07"
        ixy="-1.4237E-13"
        ixz="-2.483E-13"
        iyy="4.2946E-07"
        iyz="3.8655E-08"
        izz="1.6162E-07" />
    </inertial>
    <visual>
      <origin
        xyz="0 0 0"
        rpy="0 0 0" />
      <geometry>
        <mesh
          filename="file://$(find rm_description)/meshes/gripper/gripper_Link4.STL" />
      </geometry>
      <material
        name="">
        <color
          rgba="0.79216 0.81961 0.93333 1" />
      </material>
    </visual>
    <collision>
      <origin
        xyz="0 0 0"
        rpy="0 0 0" />
      <geometry>
        <mesh
          filename="file://$(find rm_description)/meshes/gripper/gripper_Link4.STL" />
      </geometry>
    </collision>
  </link>
  <joint
    name="gripper_joint4"
    type="revolute">
    <origin
      xyz="0 -0.022341 0.035565"
      rpy="0.8663 0 0" />
    <parent
      link="gripper_Link3" />
    <child
      link="gripper_Link4" />
    <axis
      xyz="-1 0 0" />
    <limit
      lower="-1.5708"
      upper="1.5708"
      effort="100"
      velocity="1" />
    <mimic
      joint="gripper_joint3"
      multiplier="1"
      offset="0" />
  </joint>
</robot>
